Workbook
Name 타자스킬: 스킬정보!$K$2:$K$44
Name 투수스킬: 스킬정보!$A$2:$A$36

Sheet 스탯계산기
A1: 사용자 정보 | B1: 구단 레벨 | C1: 클랜 레벨 | D1: 동일 팀 카드
B2: 100 | C2: 12 | D2: 28
B3: 바인더레벨 | C3: 100 | D3: =C3*5 -> 500
B4: 구단 | C4: 27
B5: 인물 | C5: 0
B6: 포지션 | C6: 10
B7: 등급 | C7: 17
B8: 년도 | C8: 0
C9: 합계 | D9: =SUM(C4:C8)+D3 -> 554
A11: 카드정보 | B11: 투수 | C11: 카드명 | D11: 등급 | E11: 강화 | F11: 레벨 | G11: 도감등급 | K11: 시너지 | L11: 14 | M11: %
A12: 구단 | B12: 자팀 | C12: 전병두 | D12: 에이스 | E12: 15 | F12: 100
C13: 스킬1 | D13: 스킬2 | E13: 스킬3 | F13: 등급스킬 | G13: 83 | L13: 250 | M13: 상수
C14: 커브 | D14: 라이징 무브먼트 | E14: 와일드씽
B15: 기본스탯 | C15: =IF(B11="투수","무브먼트","컨택트") -> 무브먼트 | D15: =IF(B11="투수","장타억제","갭파워") -> 장타억제 | E15: =IF(B11="투수","홈런억제","홈런파워") -> 홈런억제 | F15: =IF(B11="투수","컨트롤","선구안") -> 컨트롤 | G15: =IF(B11="투수","스터프","삼진회피") -> 스터프 | H15: =IF(B11="투수","한계투구","도루") -> 한계투구 | I15: =IF(B11="투수","주자견제","주루") -> 주자견제 | J15: 수비 | K15: 추가파워(%) | L15: 추가파워(상수)
B16: =SUM(C16:J16) -> 1899 | C16: 409 | D16: 259 | E16: 206 | F16: 237 | G16: 402 | H16: 85 | I16: 6 | J16: 295
B17: 각인1 | C17: 68 | F17: 271
B18: 각인2 | E18: 289 | F18: 20 | H18: 31
A19: 커리어 | B19: 커리어1 | C19: 커리어2 | D19: 커리어2 | E19: 커리어3 | F19: 커리어4 | G19: 커리어5 | H19: 커리어6 | I19: 추가스탯1 | J19: 추가스탯2
A20: 등급
A21: 스탯종류
A22: 스탯값
A23: 커리어환산값
B24: 스탯명 | C24: 레벨 | D24: 도감 | E24: 강화 | F24: 구단레벨 | G24: 커리어 | K24: 파워상승
B25: 스탯수치 | C25: =F12 -> 100 | D25: 900 | E25: =VLOOKUP(D12,등급정보!A1:B12,2,FALSE) -> 50 | F25: =$B$2 -> 100 | G25: 150 | K25: 24
B26: 환산수치 | C26: =IF(C25*10-10>0,C25*10-10,0) -> 990 | D26: =D25 -> 900 | E26: =E25*E12 -> 750 | F26: =IF(B12="자팀",750,500) -> 750 | G26: =IF(G25-1>0,G25-1,0) -> 149
B27: 커리어스탯
B28: 스킬1 | C28: =IF($B$11="투수", IFERROR(VLOOKUP($C$14,스킬정보!$A$2:$J$198,2,FALSE),0), IFERROR(VLOOKUP($C$14,스킬정보!$K$2:'스킬정보'!$T$198,2,FALSE),0) ) -> 15 | D28: =IF($B$11="투수", IFERROR(VLOOKUP($C$14,스킬정보!$A$2:$J$198,3,FALSE),0), IFERROR(VLOOKUP($C$14,스킬정보!$K$2:'스킬정보'!$T$198,2,FALSE),0) ) -> 10 | E28: =IF($B$11="투수", IFERROR(VLOOKUP($C$14,스킬정보!$A$2:$J$198,4,FALSE),0), IFERROR(VLOOKUP($C$14,스킬정보!$K$2:'스킬정보'!$T$198,4,FALSE),0) ) -> 0 | F28: =IF($B$11="투수", IFERROR(VLOOKUP($C$14,스킬정보!$A$2:$J$198,5,FALSE),0), IFERROR(VLOOKUP($C$14,스킬정보!$K$2:'스킬정보'!$T$198,5,FALSE),0) ) -> 0 | G28: =IF($B$11="투수", IFERROR(VLOOKUP($C$14,스킬정보!$A$2:$J$198,6,FALSE),0), IFERROR(VLOOKUP($C$14,스킬정보!$K$2:'스킬정보'!$T$198,6,FALSE),0) ) -> 0 | H28: =IF($B$11="투수", IFERROR(VLOOKUP($C$14,스킬정보!$A$2:$J$198,7,FALSE),0), IFERROR(VLOOKUP($C$14,스킬정보!$K$2:'스킬정보'!$T$198,7,FALSE),0) ) -> 0 | I28: =IF($B$11="투수", IFERROR(VLOOKUP($C$14,스킬정보!$A$2:$J$198,8,FALSE),0), IFERROR(VLOOKUP($C$14,스킬정보!$K$2:'스킬정보'!$T$198,8,FALSE),0) ) -> 0 | J28: =IF($B$11="투수", IFERROR(VLOOKUP($C$14,스킬정보!$A$2:$J$198,9,FALSE),0), IFERROR(VLOOKUP($C$14,스킬정보!$K$2:'스킬정보'!$T$198,9,FALSE),0) ) -> 0 | K28: =IF($B$11="투수", IFERROR(VLOOKUP($C$14,스킬정보!$A$2:$J$198,10,FALSE),0), IFERROR(VLOOKUP($C$14,스킬정보!$K$2:'스킬정보'!$T$198,10,FALSE),0) ) -> 0
B29: 스킬2 | C29: =IF($B$11="투수", IFERROR(VLOOKUP($D$14,스킬정보!$A$2:$J$198,2,FALSE),0), IFERROR(VLOOKUP($D$14,스킬정보!$K$2:'스킬정보'!$T$198,2,FALSE),0) ) -> 0 | D29: =IF($B$11="투수", IFERROR(VLOOKUP($D$14,스킬정보!$A$2:$J$198,3,FALSE),0), IFERROR(VLOOKUP($D$14,스킬정보!$K$2:'스킬정보'!$T$198,2,FALSE),0) ) -> 0 | E29: =IF($B$11="투수", IFERROR(VLOOKUP($D$14,스킬정보!$A$2:$J$198,4,FALSE),0), IFERROR(VLOOKUP($D$14,스킬정보!$K$2:'스킬정보'!$T$198,4,FALSE),0) ) -> 0 | F29: =IF($B$11="투수", IFERROR(VLOOKUP($D$14,스킬정보!$A$2:$J$198,5,FALSE),0), IFERROR(VLOOKUP($D$14,스킬정보!$K$2:'스킬정보'!$T$198,5,FALSE),0) ) -> 0 | G29: =IF($B$11="투수", IFERROR(VLOOKUP($D$14,스킬정보!$A$2:$J$198,6,FALSE),0), IFERROR(VLOOKUP($D$14,스킬정보!$K$2:'스킬정보'!$T$198,6,FALSE),0) ) -> 20 | H29: =IF($B$11="투수", IFERROR(VLOOKUP($D$14,스킬정보!$A$2:$J$198,7,FALSE),0), IFERROR(VLOOKUP($D$14,스킬정보!$K$2:'스킬정보'!$T$198,7,FALSE),0) ) -> 0 | I29: =IF($B$11="투수", IFERROR(VLOOKUP($D$14,스킬정보!$A$2:$J$198,8,FALSE),0), IFERROR(VLOOKUP($D$14,스킬정보!$K$2:'스킬정보'!$T$198,8,FALSE),0) ) -> 0 | J29: =IF($B$11="투수", IFERROR(VLOOKUP($D$14,스킬정보!$A$2:$J$198,9,FALSE),0), IFERROR(VLOOKUP($D$14,스킬정보!$K$2:'스킬정보'!$T$198,9,FALSE),0) ) -> 0 | K29: =IF($B$11="투수", IFERROR(VLOOKUP($D$14,스킬정보!$A$2:$J$198,10,FALSE),0), IFERROR(VLOOKUP($D$14,스킬정보!$K$2:'스킬정보'!$T$198,10,FALSE),0) ) -> 0
B30: 스킬3 | C30: =IF($B$11="투수", IFERROR(VLOOKUP($E$14,스킬정보!$A$2:$J$198,2,FALSE),0), IFERROR(VLOOKUP($E$14,스킬정보!$K$2:'스킬정보'!$T$198,2,FALSE),0) ) -> 0 | D30: =IF($B$11="투수", IFERROR(VLOOKUP($E$14,스킬정보!$A$2:$J$198,3,FALSE),0), IFERROR(VLOOKUP($E$14,스킬정보!$K$2:'스킬정보'!$T$198,2,FALSE),0) ) -> 0 | E30: =IF($B$11="투수", IFERROR(VLOOKUP($E$14,스킬정보!$A$2:$J$198,4,FALSE),0), IFERROR(VLOOKUP($E$14,스킬정보!$K$2:'스킬정보'!$T$198,4,FALSE),0) ) -> 0 | F30: =IF($B$11="투수", IFERROR(VLOOKUP($E$14,스킬정보!$A$2:$J$198,5,FALSE),0), IFERROR(VLOOKUP($E$14,스킬정보!$K$2:'스킬정보'!$T$198,5,FALSE),0) ) -> -3 | G30: =IF($B$11="투수", IFERROR(VLOOKUP($E$14,스킬정보!$A$2:$J$198,6,FALSE),0), IFERROR(VLOOKUP($E$14,스킬정보!$K$2:'스킬정보'!$T$198,6,FALSE),0) ) -> 10 | H30: =IF($B$11="투수", IFERROR(VLOOKUP($E$14,스킬정보!$A$2:$J$198,7,FALSE),0), IFERROR(VLOOKUP($E$14,스킬정보!$K$2:'스킬정보'!$T$198,7,FALSE),0) ) -> 0 | I30: =IF($B$11="투수", IFERROR(VLOOKUP($E$14,스킬정보!$A$2:$J$198,8,FALSE),0), IFERROR(VLOOKUP($E$14,스킬정보!$K$2:'스킬정보'!$T$198,8,FALSE),0) ) -> 0 | J30: =IF($B$11="투수", IFERROR(VLOOKUP($E$14,스킬정보!$A$2:$J$198,9,FALSE),0), IFERROR(VLOOKUP($E$14,스킬정보!$K$2:'스킬정보'!$T$198,9,FALSE),0) ) -> 0 | K30: =IF($B$11="투수", IFERROR(VLOOKUP($E$14,스킬정보!$A$2:$J$198,10,FALSE),0), IFERROR(VLOOKUP($E$14,스킬정보!$K$2:'스킬정보'!$T$198,10,FALSE),0) ) -> 0
P31: =32*28 -> 896
A32: 강화스탯 | B32: =SUM(C26:G26) -> 3539 | C32: =$B$32/5 -> 707.8 | D32: =$B$32/5 -> 707.8 | E32: =$B$32/5 -> 707.8 | F32: =$B$32/5 -> 707.8 | G32: =$B$32/5 -> 707.8
A33: 시너지스탯 | B33: =(B16+B32)*(L11/100)+L13 -> 1011.32 | C33: =$B$33/5 -> 202.264 | D33: =$B$33/5 -> 202.264 | E33: =$B$33/5 -> 202.264 | F33: =$B$33/5 -> 202.264 | G33: =$B$33/5 -> 202.264
A34: 자팀커작 | B34: =K25*D2 -> 672 | C34: =$B$34/5 -> 134.4 | D34: =$B$34/5 -> 134.4 | E34: =$B$34/5 -> 134.4 | F34: =$B$34/5 -> 134.4 | G34: =$B$34/5 -> 134.4
A35: 전체스킬스탯 | B35: =(B16+B32)*(SUM(K28:K30)/100) -> 0 | C35: =$B$35/5 -> 0 | D35: =$B$35/5 -> 0 | E35: =$B$35/5 -> 0 | F35: =$B$35/5 -> 0 | G35: =$B$35/5 -> 0
A36: 팀플+디그 | B36: =G13 -> 83 | C36: =$B$36/5 -> 16.6 | D36: =$B$36/5 -> 16.6 | E36: =$B$36/5 -> 16.6 | F36: =$B$36/5 -> 16.6 | G36: =$B$36/5 -> 16.6
A37: 강화스킬 | B37: =IF(OR(D12="에이스",D12="히트"),32*D2,0) -> 896 | C37: =$B$37/5 -> 179.2 | D37: =$B$37/5 -> 179.2 | E37: =$B$37/5 -> 179.2 | F37: =$B$37/5 -> 179.2 | G37: =$B$37/5 -> 179.2
A38: 각인파워 | B38: =(B32+B16)*((K17+K18)/100)+L17+L18 -> 0 | C38: =$B$38/5 -> 0 | D38: =$B$38/5 -> 0 | E38: =$B$38/5 -> 0 | F38: =$B$38/5 -> 0 | G38: =$B$38/5 -> 0
A39: 중간스탯 | B39: =SUM(B32:B38)+B16 -> 8100.32 | C39: =SUM(C32:C38)+C16 -> 1649.264 | D39: =SUM(D32:D38)+D16 -> 1499.264 | E39: =SUM(E32:E38)+E16 -> 1446.264 | F39: =SUM(F32:F38)+F16 -> 1477.264 | G39: =SUM(G32:G38)+G16 -> 1642.264
A40: 스킬1 | B40: =SUM(C40:G40) -> 397.316 | C40: =C$39*(C28/100) -> 247.3896 | D40: =D$39*(D28/100) -> 149.9264 | E40: =E$39*(E28/100) -> 0 | F40: =F$39*(F28/100) -> 0 | G40: =G$39*(G28/100) -> 0
A41: 스킬2 | B41: =SUM(C41:G41) -> 328.4528 | C41: =C$39*(C29/100) -> 0 | D41: =D$39*(D29/100) -> 0 | E41: =E$39*(E29/100) -> 0 | F41: =F$39*(F29/100) -> 0 | G41: =G$39*(G29/100) -> 328.4528
...

Sheet 커리어계산기
H1: 레벨 | I1: 필요레벨 | K1: 커구
H2: 1 | I2: 0 | J2: 0 | K2: 0 | L2: 0
H3: 2 | I3: 1 | J3: 1 | K3: 1 | L3: 1
H4: 3 | I4: 1 | J4: 2 | K4: 1 | L4: 2
A5: 커리어 레벨 | B5: 몇 포인트가 있나요? | C5: 총 보유 포인트 | D5: 측정 희망 레벨 | E5: 몇 포인트가 필요한가요 | F5: 지금 포인트로 몇레벨까지 | H5: 4 | I5: 1 | J5: 3 | K5: 1 | L5: 3
A6: 40 | B6: 1588 | C6: =VLOOKUP(A6,H2:L151,3,FALSE) + B6 -> 1691 | D6: 150 | E6: =IF(D6>A6,VLOOKUP(D6,H2:L151,3,FALSE)-C6,0) -> 2 | F6: =_xlfn.XLOOKUP(C6, J2:J151, H2:H151, , -1) -> 149 | H6: 5 | I6: 1 | J6: 4 | K6: 1 | L6: 4
H7: 6 | I7: 1 | J7: 5 | K7: 1 | L7: 5
H8: 7 | I8: 1 | J8: 6 | K8: 1 | L8: 6
H9: 8 | I9: 1 | J9: 7 | K9: 1 | L9: 7
H10: 9 | I10: 1 | J10: 8 | K10: 1 | L10: 8
H11: 10 | I11: 2 | J11: 10 | K11: 2 | L11: 10
H12: 11 | I12: 2 | J12: 12 | K12: 2 | L12: 12
H13: 12 | I13: 2 | J13: 14 | K13: 2 | L13: 14
H14: 13 | I14: 2 | J14: 16 | K14: 2 | L14: 16
H15: 14 | I15: 2 | J15: 18 | K15: 2 | L15: 18
H16: 15 | I16: 2 | J16: 20 | K16: 3 | L16: 21
H17: 16 | I17: 2 | J17: 22 | K17: 3 | L17: 24
H18: 17 | I18: 2 | J18: 24 | K18: 3 | L18: 27
... H151: 150 | I151: 20 | J151: 1693 | K151: 100 | L151: 8608

Sheet 스킬정보
A1: 이름 | B1: 무브먼트 | C1: 홈런 억제 | D1: 장타 억제 | E1: 컨트롤 | F1: 스터프 | G1: 한계투구 | H1: 주자견제 | I1: 수비 | J1: 파워 | K1: 이름 | L1: 컨택 | M1: 홈런 파워 | N1: 갭 파워 | O1: 선구 | P1: 삼진 회피 | Q1: 수비 | R1: 주루 | S1: 도루 | T1: 파워 | U1: 이름
A2: 와일드씽 | E2: -3 | F2: 10 | K2: 파워 | M2: 15 | N2: 15 | U2: 도루 저지
A3: 정면승부 | K3: 타격 전략 | L3: 20 | U3: 야전사령관
A4: 투피치 | K4: 컨택터 | L4: 20 | U4: 인사이드 워크
A5: 파이어볼러 | F5: 15 | K5: 선구안 | O5: 15 | P5: 15 | U5: 투수 리드
A6: 더티 무브먼트 | B6: 25 | K6: 대응력 | U6: 친화력
A7: 라이징 무브먼트 | F7: 20 | K7: OPS형 타자 | M7: 10 | N7: 10
A8: 묵직함 | C8: 10 | D8: 10 | K8: 적극성 | L8: 15
A9: 너클볼 | B9: 20 | C9: -5 | D9: -5 | E9: 20 | F9: 20 | K9: 갭 히터 | N9: 15
A10: 스플리터 | B10: 15 | E10: -5 | F10: 25 | K10: 게스히팅 | M10: 10 | N10: 8 | P10: -5
A11: 슬라이더 | K11: 배드볼히터 | L11: 15 | M11: 20 | O11: -3
A12: 싱커 | C12: 20 | K12: 직구 공략
A13: 체인지업 | D13: 15 | K13: 변화구 공략
A14: 커브 | B14: 15 | C14: 10 | K14: 슬랩 히터 | L14: 20 | R14: 10
A15: 에이스 | J15: 9 | K15: 펀치력 | M15: 5 | N15: 10
A16: 원투펀치 | J16: 8 | K16: 공격형 포수
A17: 롱맨 | J17: 10 | K17: 하이볼 히터 | L17: 10 | M17: -5 | P17: 5
A18: 원포인터 | J18: 10 | K18: 로우볼 히터 | M18: 10 | N18: 5 | O18: -5
A19: 믿을맨 | J19: 10 | K19: 배럴 히터 | L19: 10 | N19: 10 | P19: 10
A20: 셋업 | J20: 10 | K20: 공갈포 | L20: -7 | M20: 20 | P20: -7
A21: 클로저 | J21: 10 | K21: VS우투
A22: 스토퍼 | J22: 10 | K22: VS좌투
A23: 완급 | K23: VS언더
A24: 위기관리 | K24: 내야 수비
A25: 이닝이팅 | H25: 5 | K25: 외야 수비
A26: 셋 포지션 | K26: 그린라이트
A27: 주자 억제 | K27: 스피드스터
A28: 타자 집중 | K28: 1번 | T28: 10
A29: 그라운드볼러 | B29: -5 | C29: 10 | D29: 10 | K29: 2번 | T29: 10
A30: 로케이션 | K30: 3번 | T30: 10
A31: 팔색조 | K31: 4번 | T31: 10
A32: 맞춰잡기 | E32: 15 | H32: 10 | K32: 5번 | T32: 10
A33: 컨트롤러 | K33: 6번 | T33: 10
A34: 플라이볼피쳐 | B34: 20 | C34: -5 | K34: 7번 | T34: 10
A35: VS우타 | K35: 8번 | T35: 10
A36: VS좌타 | K36: 9번 | T36: 10
K37: 테이블세터 | T37: 7
K38: 클린업 | T38: 8
K39: 하위타선 | T39: 8
K40: 지명타자 | T40: 8.5
...

Sheet 등급정보
A1: 등급 | B1: 강화 | C1: 도감 | G1: 강화 등급
A2: 시즌 | B2: 30 | C2: 80 | G2: 0
A3: 올스타 | B3: 30 | C3: 80 | G3: 1
A4: 포스트시즌 | B4: 40 | C4: 80 | G4: 2
A5: 신인왕 | B5: 50 | C5: 100 | G5: 3
A6: MMVP | B6: 40 | C6: 90 | G6: 4 | L6: 등급 | M6: 희귀도 | N6: 1 돌파 | O6: 2 돌파 | P6: 3 돌파 | Q6: 4 돌파 | R6: 5 돌파 | S6: 6 돌파 | T6: 총 파워 상승
A7: 팀플레이어 | B7: 40 | C7: 90 | G7: 5 | L7: TOP / ACE/ HIT / GG | M7: 5성 | N7: 100 | O7: 150 | P7: 200 | Q7: 250 | R7: 300 | S7: 500 | T7: 1500
A8: 골든글러브 | B8: 50 | C8: 90 | G8: 6 | L8: ROY / TEA / MMVP | N8: 50 | O8: 100 | P8: 150 | Q8: 200 | R8: 250 | S8: 300 | T8: 1050
A9: 에이스 | B9: 50 | C9: 90 | G9: 7 | L9: 등급 | M9: 희귀도 | N9: 1 돌파 | O9: 2 돌파 | P9: 3 돌파 | Q9: 4 돌파 | R9: 5 돌파 | S9: 6 돌파 | T9: 총 파워 상승
A10: 히트 | B10: 50 | C10: 90 | G10: 8 | L10: POS / ASG/ SEA | M10: 1성 | N10: 30 | O10: 60 | P10: ​ | Q10: ​ | R10: ​ | S10: ​ | T10: 90
A11: 탑클래스 | B11: 50 | C11: 120 | G11: 9 | M11: 2성 | N11: 30 | O11: 60 | P11: 90 | Q11: ​ | R11: ​ | S11: ​ | T11: 180
A12: 디그니티 | B12: 300 | C12: 0 | G12: 10 | M12: 3성 | N12: 30 | O12: 60 | P12: 90 | Q12: 120 | R12: ​ | S12: ​ | T12: 300
G13: 11 | M13: 4성 | N13: 30 | O13: 60 | P13: 90 | Q13: 120 | R13: 150 | S13: ​ | T13: 450
G14: 12 | M14: 5성 | N14: 30 | O14: 60 | P14: 90 | Q14: 120 | R14: 150 | S14: 180 | T14: 630
G15: 13 | L15: ​
G16: 14
G17: 15 | L17: 등급_희귀도 | M17: 희귀도 | N17: 1돌파 | O17: 2돌파 | P17: 3돌파 | Q17: 4돌파 | R17: 5돌파 | S17: 6돌파
L18: SEA | M18: 1 | N18: 30 | O18: 90
L19: SEA | M19: 2 | N19: 30 | O19: 90 | P19: 180
L20: SEA | M20: 3 | N20: 30 | O20: 90 | P20: 180 | Q20: 300
L21: SEA | M21: 4 | N21: 30 | O21: 90 | P21: 180 | Q21: 300 | R21: 450
A22: GRADE_CONSTANTS = { | L22: SEA | M22: 5 | N22: 90 | O22: 90 | P22: 180 | Q22: 300 | R22: 450 | S22: 630
A23: "SEA": {"atlas": 80, "enhance": 30}, "AGS": {"atlas": 80, "enhance": 30}, | L23: POS | M23: 4 | N23: 30 | O23: 90 | P23: 180 | Q23: 300 | R23: 450
A24: "POS": {"atlas": 80, "enhance": 40}, "ROY": {"atlas": 100, "enhance": 50}, | L24: POS | M24: 5 | N24: 90 | O24: 90 | P24: 180 | Q24: 300 | R24: 450 | S24: 630
A25: "MMVP": {"atlas": 90, "enhance": 40}, "TEA": {"atlas": 90, "enhance": 40}, | L25: AGS | M25: 3 | N25: 30 | O25: 90 | P25: 180 | Q25: 300
A26: "GG": {"atlas": 90, "enhance": 50}, "ACE": {"atlas": 90, "enhance": 50}, | L26: AGS | M26: 4 | N26: 30 | O26: 90 | P26: 180 | Q26: 300 | R26: 450
A27: "HIT": {"atlas": 90, "enhance": 50}, "TOP": {"atlas": 120, "enhance": 50}, | L27: ROY | M27: 5 | N27: 50 | O27: 150 | P27: 300 | Q27: 500 | R27: 750 | S27: 1050
A28: "DGN": {"atlas": 0, "enhance": 300} | L28: TEA | M28: 5 | N28: 50 | O28: 150 | P28: 300 | Q28: 500 | R28: 750 | S28: 1050
A29: } | L29: MMVP | M29: 5 | N29: 50 | O29: 150 | P29: 300 | Q29: 500 | R29: 750 | S29: 1050
L30: TOP | M30: 5 | N30: 100 | O30: 250 | P30: 450 | Q30: 700 | R30: 1000 | S30: 1500
L31: HIT | M31: 5 | N31: 100 | O31: 250 | P31: 450 | Q31: 700 | R31: 1000 | S31: 1500
L32: ACE | M32: 5 | N32: 100 | O32: 250 | P32: 450 | Q32: 700 | R32: 1000 | S32: 1500
L33: GG | M33: 5 | N33: 100 | O33: 250 | P33: 450 | Q33: 700 | R33: 1000 | S33: 1500

Sheet 커리어 정보
A1: 종류 | B1: 스탯번호 | C1: 스탯종류 | D1: 커리어종류
A2: 컨택트 | B2: 1 | C2: 파워
A3: 갭파워 | B3: 2 | C3: 능력치
A4: 홈런파워 | B4: 3
A5: 선구안 | B5: 4
A6: 삼진회피 | B6: 5
A7: 전체능력 | B7: 0
A8: 자팀파워 | B8: 0
A10: 종류 | B10: 스탯번호
A11: 무브먼트 | B11: 1
A12: 장타억제 | B12: 2
A13: 홈런억제 | B13: 3
A14: 컨트롤 | B14: 4
A15: 스터프 | B15: 5
A16: 전체능력 | B16: 0
A17: 자팀파워 | B17: 0
F27: 기본스탯
G28: =IF(F23="투수","무브먼트","컨택트") -> 컨택트 | H28: =IF(F23="투수","장타억제","갭파워") -> 갭파워 | I28: =IF(F23="투수","홈런억제","홈런파워") -> 홈런파워 | J28: =IF(F23="투수","컨트롤","선구안") -> 선구안 | K28: =IF(F23="투수","스터프","삼진회피") -> 삼진회피 | L28: =IF(F23="투수","한계투구","도루") -> 도루 | M28: =IF(F23="투수","주자견제","주루") -> 주루 | N28: 수비
F29: 각인1 | G29: 32 | H29: 4 | I29: 272 | J29: 27 | K29: 4
F30: 각인2 | H30: 22 | J30: 307 | K30: 20

Sheet 기본정보
A1: 투수 | B1: 자팀
A2: 타자 | B2: 타팀
